[2024-11-10T17:53:34.621+0000] {taskinstance.py:1159} INFO - Dependencies all met for dep_context=non-requeueable deps ti=<TaskInstance: etl_reddit_pipeline.s3_upload scheduled__2024-11-09T00:00:00+00:00 [queued]>
[2024-11-10T17:53:34.629+0000] {taskinstance.py:1159} INFO - Dependencies all met for dep_context=requeueable deps ti=<TaskInstance: etl_reddit_pipeline.s3_upload scheduled__2024-11-09T00:00:00+00:00 [queued]>
[2024-11-10T17:53:34.629+0000] {taskinstance.py:1361} INFO - Starting attempt 1 of 1
[2024-11-10T17:53:34.638+0000] {taskinstance.py:1382} INFO - Executing <Task(PythonOperator): s3_upload> on 2024-11-09 00:00:00+00:00
[2024-11-10T17:53:34.659+0000] {standard_task_runner.py:57} INFO - Started process 53 to run task
[2024-11-10T17:53:34.666+0000] {standard_task_runner.py:84} INFO - Running: ['airflow', 'tasks', 'run', 'etl_reddit_pipeline', 's3_upload', 'scheduled__2024-11-09T00:00:00+00:00', '--job-id', '3', '--raw', '--subdir', 'DAGS_FOLDER/reddit_dag.py', '--cfg-path', '/tmp/tmpe0ltnvu2']
[2024-11-10T17:53:34.670+0000] {standard_task_runner.py:85} INFO - Job 3: Subtask s3_upload
[2024-11-10T17:53:34.728+0000] {task_command.py:416} INFO - Running <TaskInstance: etl_reddit_pipeline.s3_upload scheduled__2024-11-09T00:00:00+00:00 [running]> on host 97f6bbe1811b
[2024-11-10T17:53:34.785+0000] {taskinstance.py:1662} INFO - Exporting env vars: AIRFLOW_CTX_DAG_OWNER='Navya Racha' AIRFLOW_CTX_DAG_ID='etl_reddit_pipeline' AIRFLOW_CTX_TASK_ID='s3_upload' AIRFLOW_CTX_EXECUTION_DATE='2024-11-09T00:00:00+00:00' AIRFLOW_CTX_TRY_NUMBER='1' AIRFLOW_CTX_DAG_RUN_ID='scheduled__2024-11-09T00:00:00+00:00'
[2024-11-10T17:53:34.798+0000] {logging_mixin.py:151} INFO - <s3fs.core.S3FileSystem object at 0xffff6c4bafa0>
[2024-11-10T17:53:35.641+0000] {logging_mixin.py:151} INFO - Bucket already exists
[2024-11-10T17:53:35.717+0000] {taskinstance.py:1937} ERROR - Task failed with exception
Traceback (most recent call last):
  File "/home/airflow/.local/lib/python3.9/site-packages/s3fs/core.py", line 706, in _lsdir
    async for c in self._iterdir(
  File "/home/airflow/.local/lib/python3.9/site-packages/s3fs/core.py", line 756, in _iterdir
    async for i in it:
  File "/home/airflow/.local/lib/python3.9/site-packages/aiobotocore/paginate.py", line 30, in __anext__
    response = await self._make_request(current_kwargs)
  File "/home/airflow/.local/lib/python3.9/site-packages/aiobotocore/client.py", line 383, in _make_api_call
    raise error_class(parsed_response, operation_name)
botocore.exceptions.ClientError: An error occurred (AccessDenied) when calling the ListObjectsV2 operation: User: arn:aws:iam::571600837397:user/s3-bucket-access-user is not authorized to perform: s3:ListBucket on resource: "arn:aws:s3:::airscholar-reddit-engineering-bucket" with an explicit deny in an identity-based policy

The above exception was the direct cause of the following exception:

Traceback (most recent call last):
  File "/home/airflow/.local/lib/python3.9/site-packages/airflow/operators/python.py", line 192, in execute
    return_value = self.execute_callable()
  File "/home/airflow/.local/lib/python3.9/site-packages/airflow/operators/python.py", line 209, in execute_callable
    return self.python_callable(*self.op_args, **self.op_kwargs)
  File "/opt/airflow/pipelines/aws_s3_pipeline.py", line 9, in upload_s3_pipeline
    upload_to_s3(s3, file_path, AWS_BUCKET_NAME, file_path.split('/')[-1])
  File "/opt/airflow/etls/aws_etl.py", line 23, in upload_to_s3
    s3.put(file_path, bucket+'/raw'+s3_file_name)
  File "/home/airflow/.local/lib/python3.9/site-packages/fsspec/asyn.py", line 118, in wrapper
    return sync(self.loop, func, *args, **kwargs)
  File "/home/airflow/.local/lib/python3.9/site-packages/fsspec/asyn.py", line 103, in sync
    raise return_result
  File "/home/airflow/.local/lib/python3.9/site-packages/fsspec/asyn.py", line 56, in _runner
    result[0] = await coro
  File "/home/airflow/.local/lib/python3.9/site-packages/fsspec/asyn.py", line 536, in _put
    trailing_sep(rpath) or await self._isdir(rpath)
  File "/home/airflow/.local/lib/python3.9/site-packages/s3fs/core.py", line 1411, in _isdir
    return bool(await self._lsdir(path))
  File "/home/airflow/.local/lib/python3.9/site-packages/s3fs/core.py", line 719, in _lsdir
    raise translate_boto_error(e)
PermissionError: User: arn:aws:iam::571600837397:user/s3-bucket-access-user is not authorized to perform: s3:ListBucket on resource: "arn:aws:s3:::airscholar-reddit-engineering-bucket" with an explicit deny in an identity-based policy
[2024-11-10T17:53:35.742+0000] {taskinstance.py:1400} INFO - Marking task as FAILED. dag_id=etl_reddit_pipeline, task_id=s3_upload, execution_date=20241109T000000, start_date=20241110T175334, end_date=20241110T175335
[2024-11-10T17:53:35.754+0000] {standard_task_runner.py:104} ERROR - Failed to execute job 3 for task s3_upload (User: arn:aws:iam::571600837397:user/s3-bucket-access-user is not authorized to perform: s3:ListBucket on resource: "arn:aws:s3:::airscholar-reddit-engineering-bucket" with an explicit deny in an identity-based policy; 53)
[2024-11-10T17:53:35.791+0000] {local_task_job_runner.py:228} INFO - Task exited with return code 1
[2024-11-10T17:53:35.817+0000] {taskinstance.py:2778} INFO - 0 downstream tasks scheduled from follow-on schedule check
